2019-07-12 23:36:24,611 ERROR: Exception on /auth/login [GET] [in /home/lomolo/Projects/microblog/venv/local/lib/python2.7/site-packages/flask/app.py:1891]
Traceback (most recent call last):
  File "/home/lomolo/Projects/microblog/venv/local/lib/python2.7/site-packages/flask/app.py", line 2446, in wsgi_app
    response = self.full_dispatch_request()
  File "/home/lomolo/Projects/microblog/venv/local/lib/python2.7/site-packages/flask/app.py", line 1951, in full_dispatch_request
    rv = self.handle_user_exception(e)
  File "/home/lomolo/Projects/microblog/venv/local/lib/python2.7/site-packages/flask/app.py", line 1820, in handle_user_exception
    reraise(exc_type, exc_value, tb)
  File "/home/lomolo/Projects/microblog/venv/local/lib/python2.7/site-packages/flask/app.py", line 1949, in full_dispatch_request
    rv = self.dispatch_request()
  File "/home/lomolo/Projects/microblog/venv/local/lib/python2.7/site-packages/flask/app.py", line 1935, in dispatch_request
    return self.view_functions[rule.endpoint](**req.view_args)
  File "/home/lomolo/Projects/microblog/app/auth/routes.py", line 26, in login
    return render_template('auth/login.html', title='Sign In', form=form)
  File "/home/lomolo/Projects/microblog/venv/local/lib/python2.7/site-packages/flask/templating.py", line 140, in render_template
    ctx.app,
  File "/home/lomolo/Projects/microblog/venv/local/lib/python2.7/site-packages/flask/templating.py", line 120, in _render
    rv = template.render(context)
  File "/home/lomolo/Projects/microblog/venv/local/lib/python2.7/site-packages/jinja2/environment.py", line 1008, in render
    return self.environment.handle_exception(exc_info, True)
  File "/home/lomolo/Projects/microblog/venv/local/lib/python2.7/site-packages/jinja2/environment.py", line 780, in handle_exception
    reraise(exc_type, exc_value, tb)
  File "/home/lomolo/Projects/microblog/app/templates/auth/login.html", line 2, in top-level template code
    {% import 'bootstrap/wtf.html' as wtf %}
  File "/home/lomolo/Projects/microblog/app/templates/main/base.html", line 1, in top-level template code
    {% extends "bootstrap/base.html" %}
  File "/home/lomolo/Projects/microblog/venv/local/lib/python2.7/site-packages/flask_bootstrap/templates/bootstrap/base.html", line 1, in top-level template code
    {% block doc -%}
  File "/home/lomolo/Projects/microblog/venv/local/lib/python2.7/site-packages/flask_bootstrap/templates/bootstrap/base.html", line 4, in block "doc"
    {%- block html %}
  File "/home/lomolo/Projects/microblog/venv/local/lib/python2.7/site-packages/flask_bootstrap/templates/bootstrap/base.html", line 20, in block "html"
    {% block body -%}
  File "/home/lomolo/Projects/microblog/venv/local/lib/python2.7/site-packages/flask_bootstrap/templates/bootstrap/base.html", line 21, in block "body"
    {% block navbar %}
  File "/home/lomolo/Projects/microblog/app/templates/main/base.html", line 21, in block "navbar"
    <a class="navbar-brand" href="{{ url_for('index') }}">Microblog</a>
  File "/home/lomolo/Projects/microblog/venv/local/lib/python2.7/site-packages/flask/helpers.py", line 370, in url_for
    return appctx.app.handle_url_build_error(error, endpoint, values)
  File "/home/lomolo/Projects/microblog/venv/local/lib/python2.7/site-packages/flask/app.py", line 2215, in handle_url_build_error
    reraise(exc_type, exc_value, tb)
  File "/home/lomolo/Projects/microblog/venv/local/lib/python2.7/site-packages/flask/helpers.py", line 358, in url_for
    endpoint, values, method=method, force_external=external
  File "/home/lomolo/Projects/microblog/venv/local/lib/python2.7/site-packages/werkzeug/routing.py", line 2007, in build
    raise BuildError(endpoint, values, method, self)
BuildError: Could not build url for endpoint 'index'. Did you mean 'microblog.index' instead?
2019-07-12 23:36:30,751 ERROR: Exception on /favicon.ico [GET] [in /home/lomolo/Projects/microblog/venv/local/lib/python2.7/site-packages/flask/app.py:1891]
Traceback (most recent call last):
  File "/home/lomolo/Projects/microblog/venv/local/lib/python2.7/site-packages/flask/app.py", line 2446, in wsgi_app
    response = self.full_dispatch_request()
  File "/home/lomolo/Projects/microblog/venv/local/lib/python2.7/site-packages/flask/app.py", line 1951, in full_dispatch_request
    rv = self.handle_user_exception(e)
  File "/home/lomolo/Projects/microblog/venv/local/lib/python2.7/site-packages/flask/app.py", line 1815, in handle_user_exception
    return self.handle_http_exception(e)
  File "/home/lomolo/Projects/microblog/venv/local/lib/python2.7/site-packages/flask/app.py", line 1743, in handle_http_exception
    return handler(e)
  File "/home/lomolo/Projects/microblog/app/errors/handlers.py", line 7, in not_found_error
    return render_template('errors/404.html'), 404
  File "/home/lomolo/Projects/microblog/venv/local/lib/python2.7/site-packages/flask/templating.py", line 140, in render_template
    ctx.app,
  File "/home/lomolo/Projects/microblog/venv/local/lib/python2.7/site-packages/flask/templating.py", line 120, in _render
    rv = template.render(context)
  File "/home/lomolo/Projects/microblog/venv/local/lib/python2.7/site-packages/jinja2/environment.py", line 1008, in render
    return self.environment.handle_exception(exc_info, True)
  File "/home/lomolo/Projects/microblog/venv/local/lib/python2.7/site-packages/jinja2/environment.py", line 780, in handle_exception
    reraise(exc_type, exc_value, tb)
  File "/home/lomolo/Projects/microblog/app/templates/errors/404.html", line 1, in top-level template code
    {% extends "main/base.html" %}
  File "/home/lomolo/Projects/microblog/app/templates/main/base.html", line 1, in top-level template code
    {% extends "bootstrap/base.html" %}
  File "/home/lomolo/Projects/microblog/venv/local/lib/python2.7/site-packages/flask_bootstrap/templates/bootstrap/base.html", line 1, in top-level template code
    {% block doc -%}
  File "/home/lomolo/Projects/microblog/venv/local/lib/python2.7/site-packages/flask_bootstrap/templates/bootstrap/base.html", line 4, in block "doc"
    {%- block html %}
  File "/home/lomolo/Projects/microblog/venv/local/lib/python2.7/site-packages/flask_bootstrap/templates/bootstrap/base.html", line 20, in block "html"
    {% block body -%}
  File "/home/lomolo/Projects/microblog/venv/local/lib/python2.7/site-packages/flask_bootstrap/templates/bootstrap/base.html", line 21, in block "body"
    {% block navbar %}
  File "/home/lomolo/Projects/microblog/app/templates/main/base.html", line 21, in block "navbar"
    <a class="navbar-brand" href="{{ url_for('index') }}">Microblog</a>
  File "/home/lomolo/Projects/microblog/venv/local/lib/python2.7/site-packages/flask/helpers.py", line 370, in url_for
    return appctx.app.handle_url_build_error(error, endpoint, values)
  File "/home/lomolo/Projects/microblog/venv/local/lib/python2.7/site-packages/flask/app.py", line 2215, in handle_url_build_error
    reraise(exc_type, exc_value, tb)
  File "/home/lomolo/Projects/microblog/venv/local/lib/python2.7/site-packages/flask/helpers.py", line 358, in url_for
    endpoint, values, method=method, force_external=external
  File "/home/lomolo/Projects/microblog/venv/local/lib/python2.7/site-packages/werkzeug/routing.py", line 2007, in build
    raise BuildError(endpoint, values, method, self)
BuildError: Could not build url for endpoint 'index'. Did you mean 'microblog.index' instead?
2019-07-12 23:40:20,610 INFO: Microblog startup [in /home/lomolo/Projects/microblog/app/__init__.py:73]
2019-07-12 23:51:23,251 INFO: Microblog startup [in /home/lomolo/Projects/microblog/app/__init__.py:73]
2019-07-12 23:51:30,613 INFO: Microblog startup [in /home/lomolo/Projects/microblog/app/__init__.py:73]
2019-07-12 23:51:36,551 INFO: Microblog startup [in /home/lomolo/Projects/microblog/app/__init__.py:73]
2019-07-12 23:51:40,604 ERROR: Exception on /auth/login [GET] [in /home/lomolo/Projects/microblog/venv/local/lib/python2.7/site-packages/flask/app.py:1891]
Traceback (most recent call last):
  File "/home/lomolo/Projects/microblog/venv/local/lib/python2.7/site-packages/flask/app.py", line 2446, in wsgi_app
    response = self.full_dispatch_request()
  File "/home/lomolo/Projects/microblog/venv/local/lib/python2.7/site-packages/flask/app.py", line 1951, in full_dispatch_request
    rv = self.handle_user_exception(e)
  File "/home/lomolo/Projects/microblog/venv/local/lib/python2.7/site-packages/flask/app.py", line 1820, in handle_user_exception
    reraise(exc_type, exc_value, tb)
  File "/home/lomolo/Projects/microblog/venv/local/lib/python2.7/site-packages/flask/app.py", line 1949, in full_dispatch_request
    rv = self.dispatch_request()
  File "/home/lomolo/Projects/microblog/venv/local/lib/python2.7/site-packages/flask/app.py", line 1935, in dispatch_request
    return self.view_functions[rule.endpoint](**req.view_args)
  File "/home/lomolo/Projects/microblog/app/auth/routes.py", line 26, in login
    return render_template('auth/login.html', title='Sign In', form=form)
  File "/home/lomolo/Projects/microblog/venv/local/lib/python2.7/site-packages/flask/templating.py", line 140, in render_template
    ctx.app,
  File "/home/lomolo/Projects/microblog/venv/local/lib/python2.7/site-packages/flask/templating.py", line 120, in _render
    rv = template.render(context)
  File "/home/lomolo/Projects/microblog/venv/local/lib/python2.7/site-packages/jinja2/environment.py", line 1008, in render
    return self.environment.handle_exception(exc_info, True)
  File "/home/lomolo/Projects/microblog/venv/local/lib/python2.7/site-packages/jinja2/environment.py", line 780, in handle_exception
    reraise(exc_type, exc_value, tb)
  File "/home/lomolo/Projects/microblog/app/templates/auth/login.html", line 1, in top-level template code
    {% extends "main/base.html" %}
  File "/home/lomolo/Projects/microblog/venv/local/lib/python2.7/site-packages/flask/templating.py", line 60, in get_source
    return self._get_source_fast(environment, template)
  File "/home/lomolo/Projects/microblog/venv/local/lib/python2.7/site-packages/flask/templating.py", line 89, in _get_source_fast
    raise TemplateNotFound(template)
TemplateNotFound: main/base.html
