2019-07-08 22:59:56,649 ERROR: Exception on /index [GET] [in /home/lomolo/Projects/microblog/venv/local/lib/python2.7/site-packages/flask/app.py:1891]
Traceback (most recent call last):
  File "/home/lomolo/Projects/microblog/venv/local/lib/python2.7/site-packages/flask/app.py", line 2446, in wsgi_app
    response = self.full_dispatch_request()
  File "/home/lomolo/Projects/microblog/venv/local/lib/python2.7/site-packages/flask/app.py", line 1951, in full_dispatch_request
    rv = self.handle_user_exception(e)
  File "/home/lomolo/Projects/microblog/venv/local/lib/python2.7/site-packages/flask/app.py", line 1820, in handle_user_exception
    reraise(exc_type, exc_value, tb)
  File "/home/lomolo/Projects/microblog/venv/local/lib/python2.7/site-packages/flask/app.py", line 1949, in full_dispatch_request
    rv = self.dispatch_request()
  File "/home/lomolo/Projects/microblog/venv/local/lib/python2.7/site-packages/flask/app.py", line 1935, in dispatch_request
    return self.view_functions[rule.endpoint](**req.view_args)
  File "/home/lomolo/Projects/microblog/venv/local/lib/python2.7/site-packages/flask_login/utils.py", line 260, in decorated_view
    return current_app.login_manager.unauthorized()
  File "/home/lomolo/Projects/microblog/venv/local/lib/python2.7/site-packages/flask_login/login_manager.py", line 167, in unauthorized
    flash(self.login_message, category=self.login_message_category)
  File "/home/lomolo/Projects/microblog/venv/local/lib/python2.7/site-packages/flask/helpers.py", line 423, in flash
    session["_flashes"] = flashes
  File "/home/lomolo/Projects/microblog/venv/local/lib/python2.7/site-packages/werkzeug/local.py", line 351, in __setitem__
    self._get_current_object()[key] = value
  File "/home/lomolo/Projects/microblog/venv/local/lib/python2.7/site-packages/flask/sessions.py", line 103, in _fail
    "The session is unavailable because no secret "
RuntimeError: The session is unavailable because no secret key was set.  Set the secret_key on the application to something unique and secret.
2019-07-08 23:00:27,551 INFO: Microblog startup [in /home/lomolo/Projects/microblog/app/__init__.py:51]
2019-07-08 23:00:38,883 ERROR: Exception on /reset_password_request [POST] [in /home/lomolo/Projects/microblog/venv/local/lib/python2.7/site-packages/flask/app.py:1891]
Traceback (most recent call last):
  File "/home/lomolo/Projects/microblog/venv/local/lib/python2.7/site-packages/flask/app.py", line 2446, in wsgi_app
    response = self.full_dispatch_request()
  File "/home/lomolo/Projects/microblog/venv/local/lib/python2.7/site-packages/flask/app.py", line 1951, in full_dispatch_request
    rv = self.handle_user_exception(e)
  File "/home/lomolo/Projects/microblog/venv/local/lib/python2.7/site-packages/flask/app.py", line 1820, in handle_user_exception
    reraise(exc_type, exc_value, tb)
  File "/home/lomolo/Projects/microblog/venv/local/lib/python2.7/site-packages/flask/app.py", line 1949, in full_dispatch_request
    rv = self.dispatch_request()
  File "/home/lomolo/Projects/microblog/venv/local/lib/python2.7/site-packages/flask/app.py", line 1935, in dispatch_request
    return self.view_functions[rule.endpoint](**req.view_args)
  File "/home/lomolo/Projects/microblog/app/routes.py", line 153, in reset_password_request
    send_password_reset_email(user)
  File "/home/lomolo/Projects/microblog/app/email.py", line 18, in send_password_reset_email
    html_body=render_template('email/reset_password.html', user=user, token=token))
  File "/home/lomolo/Projects/microblog/app/email.py", line 10, in send_mail
    mail.send(msg)
  File "/home/lomolo/Projects/microblog/venv/local/lib/python2.7/site-packages/flask_mail.py", line 491, in send
    with self.connect() as connection:
  File "/home/lomolo/Projects/microblog/venv/local/lib/python2.7/site-packages/flask_mail.py", line 144, in __enter__
    self.host = self.configure_host()
  File "/home/lomolo/Projects/microblog/venv/local/lib/python2.7/site-packages/flask_mail.py", line 156, in configure_host
    host = smtplib.SMTP_SSL(self.mail.server, self.mail.port)
  File "/usr/lib/python2.7/smtplib.py", line 802, in __init__
    SMTP.__init__(self, host, port, local_hostname, timeout)
  File "/usr/lib/python2.7/smtplib.py", line 256, in __init__
    (code, msg) = self.connect(host, port)
  File "/usr/lib/python2.7/smtplib.py", line 317, in connect
    self.sock = self._get_socket(host, port, self.timeout)
  File "/usr/lib/python2.7/smtplib.py", line 808, in _get_socket
    new_socket = ssl.wrap_socket(new_socket, self.keyfile, self.certfile)
  File "/usr/lib/python2.7/ssl.py", line 931, in wrap_socket
    ciphers=ciphers)
  File "/usr/lib/python2.7/ssl.py", line 599, in __init__
    self.do_handshake()
  File "/usr/lib/python2.7/ssl.py", line 828, in do_handshake
    self._sslobj.do_handshake()
SSLError: [SSL: WRONG_VERSION_NUMBER] wrong version number (_ssl.c:727)
2019-07-08 23:01:00,548 INFO: Microblog startup [in /home/lomolo/Projects/microblog/app/__init__.py:51]
2019-07-08 23:01:10,098 ERROR: Exception on /reset_password_request [POST] [in /home/lomolo/Projects/microblog/venv/local/lib/python2.7/site-packages/flask/app.py:1891]
Traceback (most recent call last):
  File "/home/lomolo/Projects/microblog/venv/local/lib/python2.7/site-packages/flask/app.py", line 2446, in wsgi_app
    response = self.full_dispatch_request()
  File "/home/lomolo/Projects/microblog/venv/local/lib/python2.7/site-packages/flask/app.py", line 1951, in full_dispatch_request
    rv = self.handle_user_exception(e)
  File "/home/lomolo/Projects/microblog/venv/local/lib/python2.7/site-packages/flask/app.py", line 1820, in handle_user_exception
    reraise(exc_type, exc_value, tb)
  File "/home/lomolo/Projects/microblog/venv/local/lib/python2.7/site-packages/flask/app.py", line 1949, in full_dispatch_request
    rv = self.dispatch_request()
  File "/home/lomolo/Projects/microblog/venv/local/lib/python2.7/site-packages/flask/app.py", line 1935, in dispatch_request
    return self.view_functions[rule.endpoint](**req.view_args)
  File "/home/lomolo/Projects/microblog/app/routes.py", line 153, in reset_password_request
    send_password_reset_email(user)
  File "/home/lomolo/Projects/microblog/app/email.py", line 18, in send_password_reset_email
    html_body=render_template('email/reset_password.html', user=user, token=token))
  File "/home/lomolo/Projects/microblog/app/email.py", line 10, in send_mail
    mail.send(msg)
  File "/home/lomolo/Projects/microblog/venv/local/lib/python2.7/site-packages/flask_mail.py", line 491, in send
    with self.connect() as connection:
  File "/home/lomolo/Projects/microblog/venv/local/lib/python2.7/site-packages/flask_mail.py", line 144, in __enter__
    self.host = self.configure_host()
  File "/home/lomolo/Projects/microblog/venv/local/lib/python2.7/site-packages/flask_mail.py", line 156, in configure_host
    host = smtplib.SMTP_SSL(self.mail.server, self.mail.port)
  File "/usr/lib/python2.7/smtplib.py", line 802, in __init__
    SMTP.__init__(self, host, port, local_hostname, timeout)
  File "/usr/lib/python2.7/smtplib.py", line 256, in __init__
    (code, msg) = self.connect(host, port)
  File "/usr/lib/python2.7/smtplib.py", line 317, in connect
    self.sock = self._get_socket(host, port, self.timeout)
  File "/usr/lib/python2.7/smtplib.py", line 808, in _get_socket
    new_socket = ssl.wrap_socket(new_socket, self.keyfile, self.certfile)
  File "/usr/lib/python2.7/ssl.py", line 931, in wrap_socket
    ciphers=ciphers)
  File "/usr/lib/python2.7/ssl.py", line 599, in __init__
    self.do_handshake()
  File "/usr/lib/python2.7/ssl.py", line 828, in do_handshake
    self._sslobj.do_handshake()
SSLError: [SSL: WRONG_VERSION_NUMBER] wrong version number (_ssl.c:727)
2019-07-08 23:02:14,439 INFO: Microblog startup [in /home/lomolo/Projects/microblog/app/__init__.py:51]
